Workbook

Sheet Indicators and Framework Map 
A1: AI Governance
A2: ID | B2: Indicators | C2: Supporting Framework(s) | D2: Regulatory Anchor
A3: AIG-01 | B3: Board / top-management-approved responsible-AI policy or principles. | C3: NIST AI RMF Govern 1.2 & 1.4; ISO 42001:2023 Cl.5.2, Annex A.2
A4: AIG-02 | B4: Board / committee oversight of AI with a named senior owner (e.g. CAIO or accountable executive). | C4: NIST AI RMF Govern 2.1 & 2.3; ISO 42001:2023 Cl.5.3 | D4: FCA/PRA Senior Manager Regime
A5: AIG-03 | B5: Defined AI roles, responsibilities and competence / resourcing. | C5: NIST AI RMF Govern 2.1 & 2.2; ISO 42001:2023 Cl.5.3, Annex A.3.2
A6: AIG-04 | B6: Documented AI risk assessment process and stated AI risk appetite / tolerance. | C6: NIST AI RMF Govern 1.3, Manage 1 & Map 1.3; ISO 42001:2023 Cl.6.1.2
A7: AIG-05 | B7: AI/ML brought within the firm's model risk management framework. | C7: –– | D7: PRA SS1/23 - Model Risk Management
A8: AIG-06 | B8: AI system / model inventory maintained. | C8: NIST AI RMF Govern 1.6; ISO 42001:2023 Annex A.4 | D8: PRA SS1/23 - Model Risk Management
A9: AIG-07 | B9: Responsible-AI lifecycle controls (development → validation/V&V → operation). | C9: NIST AI RMF Map, Measure & Manage 4.1; ISO 42001:2023 Annex A.6
A10: AIG-08 | B10: Data governance for AI (data quality, provenance, lineage). | C10: NIST AI RMF Map 4; ISO 42001:2023 Annex A.7
A11: AIG-09 | B11: AI impact assessment on customers / individuals. | C11: ISO 42001:2023 Cl.6.1.4
A12: AIG-10 | B12: Fairness and harmful-bias management. | C12: NIST AI RMF Section 3.7 & Measure 2
A13: AIG-11 | B13: Transparency and explainability to users / affected parties. | C13: NIST AI RMF Section 3.4 & 3.5, Measure 2.8, 2,9 & 2.11; ISO 42001:2023 Annex A.8
A14: AIG-12 | B14: Third-party / vendor AI risk governance. | C14: NIST AI RMF Govern 6 & Manage 3.1; ISO 42001:2023 Annex A.10
A15: AIG-13 | B15: Monitoring and measurement of AI performance and controls. | C15: NIST AI RMF Measure; ISO 42001:2023 Cl.9.1
A16: AIG-14 | B16: AI testing, incident management and escalation. | C16: NIST AI RMF Govern 4.3 & Manage 4.3
A17: AIG-15 | B17: Independent assurance / audit / management review of AI governance. | C17: NIST AI RMF Measure 1.3; ISO 42001:2023 Cl.9.2, 9.3, 10.1
A18: Cybersecurity Governance
A19: ID | B19: Indicators | C19: Supporting Framework(s) | D19: Regulatory Anchor
A20: CYG-01 | B20: Board-approved cybersecurity / information-security policy. | C20: NIST CSF GV.PO; ISO 27001:2022 Cl.5.2
A21: CYG-02 | B21: Board oversight of cyber risk with a named senior owner (CISO). | C21: NIST CSF GV.RR; ISO 27001:2022 Cl.5.3
A22: CYG-03 | B22: Cyber risk embedded in enterprise risk-management strategy. | C22: NIST CSF GV.RM; ISO 27001:2022 Cl.6.1
A23: CYG-04 | B23: Documented cyber risk assessment and stated risk appetite. | C23: NIST CSF ID.RA; ISO 27001:2022 Cl.6.1.2
A24: CYG-05 | B24: Asset inventory / asset management. | C24: NIST CSF ID.AM; ISO 27001:2022 Annex A.5.9
A25: CYG-06 | B25: Supply-chain / third-party cyber risk governance. | C25: NIST CSF GV.SC; ISO 27001:2022 Annex A.5.21
A26: CYG-07 | B26: Access control and identity management. | C26: NIST CSF PR.AA; ISO 27001:2022 Annex A.5.15 – 5.18 & Annex 8.5 & 8.11
A27: CYG-08 | B27: Data security (confidentiality, integrity, availability). | C27: NIST CSF PR.DS; ISO 27001:2022 Annex A.7.12, 7.14, 8.11, & 8.12
A28: CYG-09 | B28: Operational resilience / ICT continuity. | C28: NIST CSF RC; ISO 27001:2022 Annex A.5.29 & A.5.30
A29: CYG-10 | B29: Continuous monitoring / threat detection. | C29: NIST CSF DE.CM; ISO 27001:2022 Cl.9.1, Annex A.8.16
A30: CYG-11 | B30: Incident response and management. | C30: NIST CSF RS ; ISO 27001:2022 Annex A.5.24
A31: CYG-12 | B31: Threat-led penetration / resilience testing. | C31: NIST CSF ID.RA & DE; ISO 27001:2022 Annex A.8.34
... A34: CYG-15 | B34: Independent assurance / audit / management review. | C34: NIST CSF 2.0 GV.OV; ISO 27001 Cl.9.2, 9.3
A35: Integration
A36: ID | B36: Indicators | C36: Supporting Framework(s) | D36: Regulatory Anchor
A37: INT-01 | B37: A single committee / board body owns BOTH AI and cyber. | C37: NIST AI RMF Govern 2.1 + NIST CSF GV.RR
A38: INT-02 | B38: CISO remit explicitly includes AI / joint accountability. | C38: NIST AI RMF Govern 2.3 + NIST CSF GV.RR
A39: INT-03 | B39: Board reporting presents AI and cyber risk together. | C39: NIST AI RMF Govern 4.2 + NIST CSF GV.OV
A40: INT-04 | B40: AI risk recorded in the enterprise / cyber risk register. | C40: NIST AI RMF Section 1.2.4 + NIST CSF GV.RM
A41: INT-05 | B41: Shared risk taxonomy across AI and cyber. | C41: NIST AI RMF Section 1.2.4 + NIST CSF GV.RM
A42: INT-06 | B42: AI sits within BOTH the model-risk and cyber-risk frameworks. | C42: Governance-Level Expectation | D42: PRA SS1/23 - Model Risk Management + CSF Risk Management
...

Sheet Worksheet
A1: Firm | B1: AI | C1: Cyber | D1: Integration | E1: Gap | Q1: AI | R1: Cyber | S1: Integration | T1: Gap
A2: HSBC | B2: =HSBC!B51 -> 2.8 | C2: =HSBC!B52 -> 3.8 | D2: =HSBC!B53 -> 2.5333333 | E2: =(C2-B2) -> 1 | P2: Bank | Q2: =IFERROR(AVERAGE(B2,B3,B4), "") -> 2.9333333 | R2: =IFERROR(ROUND(AVERAGE(C2,C3,C4),2),"") -> 3.49 | S2: =IFERROR(ROUND(AVERAGE(D2,D3,D4),2),"") -> 2.49 | T2: =(R2-Q2) -> 0.55666667
A3: Barclays | B3: =Barclays!B51 -> 3 | C3: =Barclays!B52 -> 3.7333333 | D3: =Barclays!B53 -> 2.6666667 | E3: =(C3-B3) -> 0.73333333 | P3: Insurance | Q3: =IFERROR(ROUND(AVERAGE(B5,B6,B7),2),"") -> 2.47 | R3: =IFERROR(ROUND(AVERAGE(C5,C6,C7),2),"") -> 2.76 | S3: =IFERROR(ROUND(AVERAGE(D5,D6,D7),2),"") -> 1.93 | T3: =(R3-Q3) -> 0.29
A4: Lloyds | B4: =Lloyds!B51 -> 3 | C4: =Lloyds!B52 -> 2.9333333 | D4: =Lloyds!B53 -> 2.2666667 | E4: =(C4-B4) -> -0.066666667 | P4: Asset Management | Q4: =IFERROR(ROUND(AVERAGE(B8,B9,B10),2),"") -> 2.13 | R4: =IFERROR(ROUND(AVERAGE(C8,C9,C10),2),"") -> 2.82 | S4: =IFERROR(ROUND(AVERAGE(D8,D9,D10),2),"") -> 1.89 | T4: =(R4-Q4) -> 0.69
A5: Aviva | B5: =Aviva!B51 -> 1.8 | C5: =Aviva!B52 -> 2.3333333 | D5: =Aviva!B53 -> 1.2666667 | E5: =(C5-B5) -> 0.53333333 | P5: Financial Management | Q5: =IFERROR(ROUND(AVERAGE(B11,B12,B13),2),"") -> 2.38 | R5: =IFERROR(ROUND(AVERAGE(C11,C12,C13),2),"") -> 3.24 | S5: =IFERROR(ROUND(AVERAGE(D11:D13),2),"") -> 2.29 | T5: =(R5-Q5) -> 0.86
A6: Legal & General | B6: =LG!B51 -> 2.6 | C6: =LG!B52 -> 2.7333333 | D6: =LG!B53 -> 2.0666667 | E6: =(C6-B6) -> 0.13333333
A7: Prudential | B7: =Prudential!B51 -> 3 | C7: =Prudential!B52 -> 3.2 | D7: =Prudential!B53 -> 2.4666667 | E7: =(C7-B7) -> 0.2
A8: 3i Group | B8: ='3i'!B51 -> 1.2666667 | C8: ='3i'!B52 -> 2.7333333 | D8: ='3i'!B53 -> 1.4666667 | E8: =(C8-B8) -> 1.4666667
A9: M & G | B9: =MG!B51 -> 2.3333333 | C9: =MG!B52 -> 2.4666667 | D9: =MG!B53 -> 1.9333333 | E9: =(C9-B9) -> 0.13333333
A10: Schroders | B10: =Schroders!B51 -> 2.8 | C10: =Schroders!B52 -> 3.2666667 | D10: =Schroders!B53 -> 2.2666667 | E10: =(C10-B10) -> 0.46666667
A11: LSEG | B11: =LSEG!B51 -> 2.3333333 | C11: =LSEG!B52 -> 2.9333333 | D11: =LSEG!B53 -> 2.0666667 | E11: =(C11-B11) -> 0.6
A12: Experian | B12: =Experian!B51 -> 3.2 | C12: =Experian!B52 -> 3.5333333 | D12: =Experian!B53 -> 2.7333333 | E12: =(C12-B12) -> 0.33333333
A13: Wise | B13: =Wise!B51 -> 1.6 | C13: =Wise!B52 -> 3.2666667 | D13: =Wise!B53 -> 2.0666667 | E13: =(C13-B13) -> 1.6666667
A15: Descriptive Statistic for Disclosed Governance Maturity Model
A16: Mean | B16: =IFERROR(ROUND(AVERAGE(B2:B13),2),"") -> 2.48 | C16: =IFERROR(ROUND(AVERAGE(C2,C3,C4,C5,C6,C7,C8,C9,C10,C11,C12,C13),2),"") -> 3.08 | D16: =IFERROR(AVERAGE(D2,D3,D4,D5,D6,D7,D8,D9,D10,D11,D12,D13), "") -> 2.15
A17: SD | B17: =ROUND(STDEV(B2:B13),2) -> 0.63 | C17: =ROUND(STDEV(C2:C13),2) -> 0.47 | D17: =ROUND(STDEV(D2:D13),2) -> 0.45
A18: Min | B18: =ROUND(MIN(B2:B13),2) -> 1.27 | C18: =ROUND(MIN(C2:C13),2) -> 2.33 | D18: =ROUND(MIN(D2:D13),2) -> 1.27
A19: Max | B19: =ROUND(MAX(B2:B13),2) -> 3.2 | C19: =ROUND(MAX(C2:C13),2) -> 3.8 | D19: =ROUND(MAX(D2:D13),2) -> 2.73
Q27: Ingration Score Mean As Per Dimensions
S29: HSBC | T29: BARCLAYS | U29: Lloyds | V29: Aviva | W29: LG | X29: Prudential | Y29: 3i | Z29: MG | AA29: Schroders | AB29: LSEG | AC29: Experian | AD29: Wise | AE29: Mean
Q30: Leadership & Accountability | S30: =HSBC!E58 -> 3.3333333 | T30: =Barclays!E58 -> 3 | U30: =Lloyds!E58 -> 2.3333333 | V30: =Aviva!E58 -> 1 | W30: =LG!E58 -> 2 | X30: =Prudential!E58 -> 2.3333333 | Y30: ='3i'!E58 -> 2 | Z30: =MG!E58 -> 2 | AA30: =Schroders!E58 -> 2.6666667 | AB30: =LSEG!E58 -> 2.3333333 | AC30: =Experian!E58 -> 2.6666667 | AD30: =Wise!E58 -> 2.3333333 | AE30: =IFERROR(ROUND(AVERAGE(S30:AD30),2),"") -> 2.33
Q31: Risk Management | S31: =HSBC!E59 -> 2.6666667 | T31: =Barclays!E59 -> 2.6666667 | U31: =Lloyds!E59 -> 3 | V31: =Aviva!E59 -> 1 | W31: =LG!E59 -> 2.3333333 | X31: =Prudential!E59 -> 2.3333333 | Y31: ='3i'!E59 -> 1.3333333 | Z31: =MG!E59 -> 2 | AA31: =Schroders!E59 -> 2.3333333 | AB31: =LSEG!E59 -> 2.6666667 | AC31: =Experian!E59 -> 3 | AD31: =Wise!E59 -> 3 | AE31: =IFERROR(ROUND(AVERAGE(S31:AD31),2),"") -> 2.36
Q32: Assurance & Improvement | S32: =HSBC!E59 -> 2.6666667 | T32: =Barclays!E60 -> 3 | U32: =Lloyds!E60 -> 2.3333333 | V32: =Aviva!E60 -> 1.6666667 | W32: =LG!E60 -> 2.3333333 | X32: =Prudential!E60 -> 2.6666667 | Y32: ='3i'!E60 -> 1.6666667 | Z32: =MG!E60 -> 2 | AA32: =Schroders!E60 -> 2.6666667 | AB32: =LSEG!E60 -> 2.3333333 | AC32: =Experian!E60 -> 3 | AD32: =Wise!E60 -> 2 | AE32: =IFERROR(ROUND(AVERAGE(S32:AD32),2),"") -> 2.36
Q33: Lifecycle & Data | S33: =HSBC!E61 -> 2.33 | T33: =Barclays!E63 -> 2.67 | U33: =Lloyds!E63 -> 2.33 | V33: =Aviva!E63 -> 1.33 | W33: =LG!E63 -> 2.33 | X33: =Prudential!E63 -> 2.67 | Y33: ='3i'!E63 -> 1 | Z33: =MG!E63 -> 2.33 | AA33: =Schroders!E63 -> 2 | AB33: =LSEG!E63 -> 1.67 | AC33: =Experian!E63 -> 3 | AD33: =Wise!E63 -> 1.67 | AE33: =IFERROR(ROUND(AVERAGE(S33:AD33),2),"") -> 2.11
Q34: Detect & Response | S34: =HSBC!E62 -> 1.67 | T34: =Barclays!E64 -> 2 | U34: =Lloyds!E64 -> 1.33 | V34: =Aviva!E64 -> 1.33 | W34: =LG!E64 -> 1.33 | X34: =Prudential!E64 -> 2.33 | Y34: ='3i'!E64 -> 1.33 | Z34: =MG!E64 -> 1.33 | AA34: =Schroders!E64 -> 1.67 | AB34: =LSEG!E64 -> 1.33 | AC34: =Experian!E64 -> 2 | AD34: =Wise!E64 -> 1.33 | AE34: =IFERROR(ROUND(AVERAGE(S34:AD34),2),"") -> 1.58
AE41: Average Integration score
AD42: Leadership & Accountability | AE42: 2.33 | AF42: =(5-AE42) -> 2.67
AD43: Risk Management | AE43: 2.36 | AF43: =(5-AE43) -> 2.64
AD44: Assurance & Improvement | AE44: 2.36 | AF44: =(5-AE44) -> 2.64
AD45: Lifecycle & Data | AE45: 2.11 | AF45: =(5-AE45) -> 2.89
AD46: Detect & Response | AE46: 1.58 | AF46: =(5-AE46) -> 3.42
C48: Cybersecurity Indicators
C49: Cyber risk embedded in enterprise risk-management strategy. | D49: =AVERAGE(HSBC:Wise!E21) -> 3.75
C50: Operational resilience / ICT continuity. | D50: =(ROUND(AVERAGE(HSBC:Wise!E27),2)) -> 3.67
C51: Board-approved cybersecurity / information-security policy. | D51: =(ROUND(AVERAGE(HSBC:Wise!E19),2)) -> 3.58
C52: Board oversight of cyber risk with a named senior owner (CISO). | D52: =(ROUND(AVERAGE(HSBC:Wise!E20),2)) -> 3.5
C53: Asset inventory / asset management. | D53: =(ROUND(AVERAGE(HSBC:Wise!E23),2)) -> 1.58
C54: Access control and identity management. | D54: =(ROUND(AVERAGE(HSBC:Wise!E25),2)) -> 2.08
C55: Threat-led penetration / resilience testing. | D55: =(ROUND(AVERAGE(HSBC:Wise!E30),2)) -> 2.25
C56: Security awareness and training. | D56: =(ROUND(AVERAGE(HSBC:Wise!E32),2)) -> 2.5
...

Sheet Worksheet 2
C1: HSBC | D1: Barclays | E1: Lloyds | F1: Aviva | G1: LG | H1: Prudential | I1: 3i | J1: MG | K1: Schroders | L1: LSEG | M1: Experian | N1: Wise | O1: Mean | P1: Firms>=3 | Q1: Firms >=4
A2: ID | B2: AI Indicators
A3: AIG-01 | B3: Board / top-management-approved responsible-AI policy or principles. | C3: =VLOOKUP($B3, HSBC!$D:$E, 2, FALSE) -> 3 | D3: =VLOOKUP($B3, Barclays!$D:$E, 2, FALSE) -> 4 | E3: =VLOOKUP($B3, Lloyds!$D:$E, 2, FALSE) -> 4 | F3: =VLOOKUP($B3, Aviva!$D:$E, 2, FALSE) -> 2 | G3: =VLOOKUP($B3, LG!$D:$E, 2, FALSE) -> 3 | H3: =VLOOKUP($B3, Prudential!$D:$E, 2, FALSE) -> 4 | I3: =VLOOKUP($B3, '3i'!$D:$E, 2, FALSE) -> 2 | J3: =VLOOKUP($B3, MG!$D:$E, 2, FALSE) -> 3 | K3: =VLOOKUP($B3, Schroders!$D:$E, 2, FALSE) -> 4 | L3: =VLOOKUP($B3, LSEG!$D:$E, 2, FALSE) -> 2 | M3: =VLOOKUP($B3, Experian!$D:$E, 2, FALSE) -> 4 | N3: =VLOOKUP($B3, Wise!$D:$E, 2, FALSE) -> 1 | O3: =ROUND(AVERAGE($C3:$N3), 2) -> 3 | P3: =COUNTIF($C3:$N3, ">=3") & "/12" -> 8/12 | Q3: =COUNTIF($C3:$N3, ">=4") & "/12" -> 5/12
A4: AIG-02 | B4: Board / committee oversight of AI with a named senior owner (e.g. CAIO or accountable executive). | C4: =VLOOKUP($B4, HSBC!$D:$E, 2, FALSE) -> 3 | D4: =VLOOKUP($B4, Barclays!$D:$E, 2, FALSE) -> 4 | E4: =VLOOKUP($B4, Lloyds!$D:$E, 2, FALSE) -> 4 | F4: =VLOOKUP($B4, Aviva!$D:$E, 2, FALSE) -> 2 | G4: =VLOOKUP($B4, LG!$D:$E, 2, FALSE) -> 3 | H4: =VLOOKUP($B4, Prudential!$D:$E, 2, FALSE) -> 3 | I4: =VLOOKUP($B4, '3i'!$D:$E, 2, FALSE) -> 2 | J4: =VLOOKUP($B4, MG!$D:$E, 2, FALSE) -> 3 | K4: =VLOOKUP($B4, Schroders!$D:$E, 2, FALSE) -> 4 | L4: =VLOOKUP($B4, LSEG!$D:$E, 2, FALSE) -> 2 | M4: =VLOOKUP($B4, Experian!$D:$E, 2, FALSE) -> 4 | N4: =VLOOKUP($B4, Wise!$D:$E, 2, FALSE) -> 2 | O4: =ROUND(AVERAGE($C4:$N4), 2) -> 3 | P4: =COUNTIF($C4:$N4, ">=3") & "/12" -> 8/12 | Q4: =COUNTIF($C4:$N4, ">=4") & "/12" -> 4/12
A5: AIG-03 | B5: Defined AI roles, responsibilities and competence / resourcing. | C5: =VLOOKUP($B5, HSBC!$D:$E, 2, FALSE) -> 4 | D5: =VLOOKUP($B5, Barclays!$D:$E, 2, FALSE) -> 3 | E5: =VLOOKUP($B5, Lloyds!$D:$E, 2, FALSE) -> 3 | F5: =VLOOKUP($B5, Aviva!$D:$E, 2, FALSE) -> 2 | G5: =VLOOKUP($B5, LG!$D:$E, 2, FALSE) -> 3 | H5: =VLOOKUP($B5, Prudential!$D:$E, 2, FALSE) -> 3 | I5: =VLOOKUP($B5, '3i'!$D:$E, 2, FALSE) -> 1 | J5: =VLOOKUP($B5, MG!$D:$E, 2, FALSE) -> 3 | K5: =VLOOKUP($B5, Schroders!$D:$E, 2, FALSE) -> 3 | L5: =VLOOKUP($B5, LSEG!$D:$E, 2, FALSE) -> 2 | M5: =VLOOKUP($B5, Experian!$D:$E, 2, FALSE) -> 3 | N5: =VLOOKUP($B5, Wise!$D:$E, 2, FALSE) -> 1 | O5: =ROUND(AVERAGE($C5:$N5), 2) -> 2.58 | P5: =COUNTIF($C5:$N5, ">=3") & "/12" -> 8/12 | Q5: =COUNTIF($C5:$N5, ">=4") & "/12" -> 1/12
A6: AIG-04 | B6: Documented AI risk assessment process and stated AI risk appetite / tolerance. | C6: =VLOOKUP($B6, HSBC!$D:$E, 2, FALSE) -> 3 | D6: =VLOOKUP($B6, Barclays!$D:$E, 2, FALSE) -> 3 | E6: =VLOOKUP($B6, Lloyds!$D:$E, 2, FALSE) -> 3 | F6: =VLOOKUP($B6, Aviva!$D:$E, 2, FALSE) -> 2 | G6: =VLOOKUP($B6, LG!$D:$E, 2, FALSE) -> 3 | H6: =VLOOKUP($B6, Prudential!$D:$E, 2, FALSE) -> 3 | I6: =VLOOKUP($B6, '3i'!$D:$E, 2, FALSE) -> 2 | J6: =VLOOKUP($B6, MG!$D:$E, 2, FALSE) -> 3 | K6: =VLOOKUP($B6, Schroders!$D:$E, 2, FALSE) -> 3 | L6: =VLOOKUP($B6, LSEG!$D:$E, 2, FALSE) -> 3 | M6: =VLOOKUP($B6, Experian!$D:$E, 2, FALSE) -> 4 | N6: =VLOOKUP($B6, Wise!$D:$E, 2, FALSE) -> 2 | O6: =ROUND(AVERAGE($C6:$N6), 2) -> 2.83 | P6: =COUNTIF($C6:$N6, ">=3") & "/12" -> 9/12 | Q6: =COUNTIF($C6:$N6, ">=4") & "/12" -> 1/12
A7: AIG-05 | B7: AI/ML brought within the firm's model risk management framework. | C7: =VLOOKUP($B7, HSBC!$D:$E, 2, FALSE) -> 4 | D7: =VLOOKUP($B7, Barclays!$D:$E, 2, FALSE) -> 4 | E7: =VLOOKUP($B7, Lloyds!$D:$E, 2, FALSE) -> 4 | F7: =VLOOKUP($B7, Aviva!$D:$E, 2, FALSE) -> 2 | G7: =VLOOKUP($B7, LG!$D:$E, 2, FALSE) -> 3 | H7: =VLOOKUP($B7, Prudential!$D:$E, 2, FALSE) -> 3 | I7: =VLOOKUP($B7, '3i'!$D:$E, 2, FALSE) -> 1 | J7: =VLOOKUP($B7, MG!$D:$E, 2, FALSE) -> 2 | K7: =VLOOKUP($B7, Schroders!$D:$E, 2, FALSE) -> 2 | L7: =VLOOKUP($B7, LSEG!$D:$E, 2, FALSE) -> 4 | M7: =VLOOKUP($B7, Experian!$D:$E, 2, FALSE) -> 3 | N7: =VLOOKUP($B7, Wise!$D:$E, 2, FALSE) -> 2 | O7: =ROUND(AVERAGE($C7:$N7), 2) -> 2.83 | P7: =COUNTIF($C7:$N7, ">=3") & "/12" -> 7/12 | Q7: =COUNTIF($C7:$N7, ">=4") & "/12" -> 4/12
A8: AIG-06 | B8: AI system / model inventory maintained. | C8: =VLOOKUP($B8, HSBC!$D:$E, 2, FALSE) -> 3 | D8: =VLOOKUP($B8, Barclays!$D:$E, 2, FALSE) -> 3 | E8: =VLOOKUP($B8, Lloyds!$D:$E, 2, FALSE) -> 3 | F8: =VLOOKUP($B8, Aviva!$D:$E, 2, FALSE) -> 2 | G8: =VLOOKUP($B8, LG!$D:$E, 2, FALSE) -> 3 | H8: =VLOOKUP($B8, Prudential!$D:$E, 2, FALSE) -> 3 | I8: =VLOOKUP($B8, '3i'!$D:$E, 2, FALSE) -> 1 | J8: =VLOOKUP($B8, MG!$D:$E, 2, FALSE) -> 2 | K8: =VLOOKUP($B8, Schroders!$D:$E, 2, FALSE) -> 2 | L8: =VLOOKUP($B8, LSEG!$D:$E, 2, FALSE) -> 4 | M8: =VLOOKUP($B8, Experian!$D:$E, 2, FALSE) -> 2 | N8: =VLOOKUP($B8, Wise!$D:$E, 2, FALSE) -> 1 | O8: =ROUND(AVERAGE($C8:$N8), 2) -> 2.42 | P8: =COUNTIF($C8:$N8, ">=3") & "/12" -> 6/12 | Q8: =COUNTIF($C8:$N8, ">=4") & "/12" -> 1/12
A9: AIG-07 | B9: Responsible-AI lifecycle controls (development → validation/V&V → operation). | C9: =VLOOKUP($B9, HSBC!$D:$E, 2, FALSE) -> 3 | D9: =VLOOKUP($B9, Barclays!$D:$E, 2, FALSE) -> 3 | E9: =VLOOKUP($B9, Lloyds!$D:$E, 2, FALSE) -> 3 | F9: =VLOOKUP($B9, Aviva!$D:$E, 2, FALSE) -> 2 | G9: =VLOOKUP($B9, LG!$D:$E, 2, FALSE) -> 3 | H9: =VLOOKUP($B9, Prudential!$D:$E, 2, FALSE) -> 3 | I9: =VLOOKUP($B9, '3i'!$D:$E, 2, FALSE) -> 1 | J9: =VLOOKUP($B9, MG!$D:$E, 2, FALSE) -> 2 | K9: =VLOOKUP($B9, Schroders!$D:$E, 2, FALSE) -> 3 | L9: =VLOOKUP($B9, LSEG!$D:$E, 2, FALSE) -> 3 | M9: =VLOOKUP($B9, Experian!$D:$E, 2, FALSE) -> 4 | N9: =VLOOKUP($B9, Wise!$D:$E, 2, FALSE) -> 1 | O9: =ROUND(AVERAGE($C9:$N9), 2) -> 2.58 | P9: =COUNTIF($C9:$N9, ">=3") & "/12" -> 8/12 | Q9: =COUNTIF($C9:$N9, ">=4") & "/12" -> 1/12
A10: AIG-08 | B10: Data governance for AI (data quality, provenance, lineage). | C10: =VLOOKUP($B10, HSBC!$D:$E, 2, FALSE) -> 3 | D10: =VLOOKUP($B10, Barclays!$D:$E, 2, FALSE) -> 3 | E10: =VLOOKUP($B10, Lloyds!$D:$E, 2, FALSE) -> 3 | F10: =VLOOKUP($B10, Aviva!$D:$E, 2, FALSE) -> 2 | G10: =VLOOKUP($B10, LG!$D:$E, 2, FALSE) -> 2 | H10: =VLOOKUP($B10, Prudential!$D:$E, 2, FALSE) -> 3 | I10: =VLOOKUP($B10, '3i'!$D:$E, 2, FALSE) -> 1 | J10: =VLOOKUP($B10, MG!$D:$E, 2, FALSE) -> 2 | K10: =VLOOKUP($B10, Schroders!$D:$E, 2, FALSE) -> 3 | L10: =VLOOKUP($B10, LSEG!$D:$E, 2, FALSE) -> 2 | M10: =VLOOKUP($B10, Experian!$D:$E, 2, FALSE) -> 4 | N10: =VLOOKUP($B10, Wise!$D:$E, 2, FALSE) -> 2 | O10: =ROUND(AVERAGE($C10:$N10), 2) -> 2.5 | P10: =COUNTIF($C10:$N10, ">=3") & "/12" -> 6/12 | Q10: =COUNTIF($C10:$N10, ">=4") & "/12" -> 1/12
A11: AIG-09 | B11: AI impact assessment on customers / individuals. | C11: =VLOOKUP($B11, HSBC!$D:$E, 2, FALSE) -> 2 | D11: =VLOOKUP($B11, Barclays!$D:$E, 2, FALSE) -> 2 | E11: =VLOOKUP($B11, Lloyds!$D:$E, 2, FALSE) -> 3 | F11: =VLOOKUP($B11, Aviva!$D:$E, 2, FALSE) -> 2 | G11: =VLOOKUP($B11, LG!$D:$E, 2, FALSE) -> 2 | H11: =VLOOKUP($B11, Prudential!$D:$E, 2, FALSE) -> 3 | I11: =VLOOKUP($B11, '3i'!$D:$E, 2, FALSE) -> 1 | J11: =VLOOKUP($B11, MG!$D:$E, 2, FALSE) -> 2 | K11: =VLOOKUP($B11, Schroders!$D:$E, 2, FALSE) -> 2 | L11: =VLOOKUP($B11, LSEG!$D:$E, 2, FALSE) -> 1 | M11: =VLOOKUP($B11, Experian!$D:$E, 2, FALSE) -> 3 | N11: =VLOOKUP($B11, Wise!$D:$E, 2, FALSE) -> 2 | O11: =ROUND(AVERAGE($C11:$N11), 2) -> 2.08 | P11: =COUNTIF($C11:$N11, ">=3") & "/12" -> 3/12 | Q11: =COUNTIF($C11:$N11, ">=4") & "/12" -> 0/12
A12: AIG-10 | B12: Fairness and harmful-bias management. | C12: =VLOOKUP($B12, HSBC!$D:$E, 2, FALSE) -> 2 | D12: =VLOOKUP($B12, Barclays!$D:$E, 2, FALSE) -> 3 | E12: =VLOOKUP($B12, Lloyds!$D:$E, 2, FALSE) -> 3 | F12: =VLOOKUP($B12, Aviva!$D:$E, 2, FALSE) -> 1 | G12: =VLOOKUP($B12, LG!$D:$E, 2, FALSE) -> 2 | H12: =VLOOKUP($B12, Prudential!$D:$E, 2, FALSE) -> 3 | I12: =VLOOKUP($B12, '3i'!$D:$E, 2, FALSE) -> 1 | J12: =VLOOKUP($B12, MG!$D:$E, 2, FALSE) -> 2 | K12: =VLOOKUP($B12, Schroders!$D:$E, 2, FALSE) -> 3 | L12: =VLOOKUP($B12, LSEG!$D:$E, 2, FALSE) -> 1 | M12: =VLOOKUP($B12, Experian!$D:$E, 2, FALSE) -> 3 | N12: =VLOOKUP($B12, Wise!$D:$E, 2, FALSE) -> 2 | O12: =ROUND(AVERAGE($C12:$N12), 2) -> 2.17 | P12: =COUNTIF($C12:$N12, ">=3") & "/12" -> 5/12 | Q12: =COUNTIF($C12:$N12, ">=4") & "/12" -> 0/12
A13: AIG-11 | B13: Transparency and explainability to users / affected parties. | C13: =VLOOKUP($B13, HSBC!$D:$E, 2, FALSE) -> 2 | D13: =VLOOKUP($B13, Barclays!$D:$E, 2, FALSE) -> 2 | E13: =VLOOKUP($B13, Lloyds!$D:$E, 2, FALSE) -> 2 | F13: =VLOOKUP($B13, Aviva!$D:$E, 2, FALSE) -> 1 | G13: =VLOOKUP($B13, LG!$D:$E, 2, FALSE) -> 2 | H13: =VLOOKUP($B13, Prudential!$D:$E, 2, FALSE) -> 2 | I13: =VLOOKUP($B13, '3i'!$D:$E, 2, FALSE) -> 1 | J13: =VLOOKUP($B13, MG!$D:$E, 2, FALSE) -> 2 | K13: =VLOOKUP($B13, Schroders!$D:$E, 2, FALSE) -> 2 | L13: =VLOOKUP($B13, LSEG!$D:$E, 2, FALSE) -> 1 | M13: =VLOOKUP($B13, Experian!$D:$E, 2, FALSE) -> 3 | N13: =VLOOKUP($B13, Wise!$D:$E, 2, FALSE) -> 1 | O13: =ROUND(AVERAGE($C13:$N13), 2) -> 1.75 | P13: =COUNTIF($C13:$N13, ">=3") & "/12" -> 1/12 | Q13: =COUNTIF($C13:$N13, ">=4") & "/12" -> 0/12
A14: AIG-12 | B14: Third-party / vendor AI risk governance. | C14: =VLOOKUP($B14, HSBC!$D:$E, 2, FALSE) -> 2 | D14: =VLOOKUP($B14, Barclays!$D:$E, 2, FALSE) -> 3 | E14: =VLOOKUP($B14, Lloyds!$D:$E, 2, FALSE) -> 2 | F14: =VLOOKUP($B14, Aviva!$D:$E, 2, FALSE) -> 2 | G14: =VLOOKUP($B14, LG!$D:$E, 2, FALSE) -> 2 | H14: =VLOOKUP($B14, Prudential!$D:$E, 2, FALSE) -> 4 | I14: =VLOOKUP($B14, '3i'!$D:$E, 2, FALSE) -> 2 | J14: =VLOOKUP($B14, MG!$D:$E, 2, FALSE) -> 2 | K14: =VLOOKUP($B14, Schroders!$D:$E, 2, FALSE) -> 3 | L14: =VLOOKUP($B14, LSEG!$D:$E, 2, FALSE) -> 2 | M14: =VLOOKUP($B14, Experian!$D:$E, 2, FALSE) -> 3 | N14: =VLOOKUP($B14, Wise!$D:$E, 2, FALSE) -> 2 | O14: =ROUND(AVERAGE($C14:$N14), 2) -> 2.42 | P14: =COUNTIF($C14:$N14, ">=3") & "/12" -> 4/12 | Q14: =COUNTIF($C14:$N14, ">=4") & "/12" -> 1/12
... A17: AIG-15 | B17: Independent assurance / audit / management review of AI governance. | C17: =VLOOKUP($B17, HSBC!$D:$E, 2, FALSE) -> 3 | D17: =VLOOKUP($B17, Barclays!$D:$E, 2, FALSE) -> 3 | E17: =VLOOKUP($B17, Lloyds!$D:$E, 2, FALSE) -> 3 | F17: =VLOOKUP($B17, Aviva!$D:$E, 2, FALSE) -> 2 | G17: =VLOOKUP($B17, LG!$D:$E, 2, FALSE) -> 3 | H17: =VLOOKUP($B17, Prudential!$D:$E, 2, FALSE) -> 3 | I17: =VLOOKUP($B17, '3i'!$D:$E, 2, FALSE) -> 1 | J17: =VLOOKUP($B17, MG!$D:$E, 2, FALSE) -> 3 | K17: =VLOOKUP($B17, Schroders!$D:$E, 2, FALSE) -> 3 | L17: =VLOOKUP($B17, LSEG!$D:$E, 2, FALSE) -> 3 | M17: =VLOOKUP($B17, Experian!$D:$E, 2, FALSE) -> 3 | N17: =VLOOKUP($B17, Wise!$D:$E, 2, FALSE) -> 2 | O17: =ROUND(AVERAGE($C17:$N17), 2) -> 2.67 | P17: =COUNTIF($C17:$N17, ">=3") & "/12" -> 9/12 | Q17: =COUNTIF($C17:$N17, ">=4") & "/12" -> 0/12
B18: Cyber Indicators
A19: CYG-01 | B19: Board-approved cybersecurity / information-security policy. | C19: =VLOOKUP($B19, HSBC!$D:$E, 2, FALSE) -> 4 | D19: =VLOOKUP($B19, Barclays!$D:$E, 2, FALSE) -> 4 | E19: =VLOOKUP($B19, Lloyds!$D:$E, 2, FALSE) -> 4 | F19: =VLOOKUP($B19, Aviva!$D:$E, 2, FALSE) -> 3 | G19: =VLOOKUP($B19, LG!$D:$E, 2, FALSE) -> 3 | H19: =VLOOKUP($B19, Prudential!$D:$E, 2, FALSE) -> 4 | I19: =VLOOKUP($B19, '3i'!$D:$E, 2, FALSE) -> 3 | J19: =VLOOKUP($B19, MG!$D:$E, 2, FALSE) -> 3 | K19: =VLOOKUP($B19, Schroders!$D:$E, 2, FALSE) -> 4 | L19: =VLOOKUP($B19, LSEG!$D:$E, 2, FALSE) -> 3 | M19: =VLOOKUP($B19, Experian!$D:$E, 2, FALSE) -> 4 | N19: =VLOOKUP($B19, Wise!$D:$E, 2, FALSE) -> 4 | O19: =ROUND(AVERAGE($C19:$N19), 2) -> 3.58 | P19: =COUNTIF($C19:$N19, ">=3") & "/12" -> 12/12 | Q19: =COUNTIF($C19:$N19, ">=4") & "/12" -> 7/12
A20: CYG-02 | B20: Board oversight of cyber risk with a named senior owner (CISO). | C20: =VLOOKUP($B20, HSBC!$D:$E, 2, FALSE) -> 4 | D20: =VLOOKUP($B20, Barclays!$D:$E, 2, FALSE) -> 4 | E20: =VLOOKUP($B20, Lloyds!$D:$E, 2, FALSE) -> 3 | F20: =VLOOKUP($B20, Aviva!$D:$E, 2, FALSE) -> 3 | G20: =VLOOKUP($B20, LG!$D:$E, 2, FALSE) -> 3 | H20: =VLOOKUP($B20, Prudential!$D:$E, 2, FALSE) -> 3 | I20: =VLOOKUP($B20, '3i'!$D:$E, 2, FALSE) -> 3 | J20: =VLOOKUP($B20, MG!$D:$E, 2, FALSE) -> 3 | K20: =VLOOKUP($B20, Schroders!$D:$E, 2, FALSE) -> 4 | L20: =VLOOKUP($B20, LSEG!$D:$E, 2, FALSE) -> 4 | M20: =VLOOKUP($B20, Experian!$D:$E, 2, FALSE) -> 4 | N20: =VLOOKUP($B20, Wise!$D:$E, 2, FALSE) -> 4 | O20: =ROUND(AVERAGE($C20:$N20), 2) -> 3.5 | P20: =COUNTIF($C20:$N20, ">=3") & "/12" -> 12/12 | Q20: =COUNTIF($C20:$N20, ">=4") & "/12" -> 6/12
A21: CYG-03 | B21: Cyber risk embedded in enterprise risk-management strategy. | C21: =VLOOKUP($B21, HSBC!$D:$E, 2, FALSE) -> 4 | D21: =VLOOKUP($B21, Barclays!$D:$E, 2, FALSE) -> 4 | E21: =VLOOKUP($B21, Lloyds!$D:$E, 2, FALSE) -> 4 | F21: =VLOOKUP($B21, Aviva!$D:$E, 2, FALSE) -> 3 | G21: =VLOOKUP($B21, LG!$D:$E, 2, FALSE) -> 4 | H21: =VLOOKUP($B21, Prudential!$D:$E, 2, FALSE) -> 4 | I21: =VLOOKUP($B21, '3i'!$D:$E, 2, FALSE) -> 3 | J21: =VLOOKUP($B21, MG!$D:$E, 2, FALSE) -> 3 | K21: =VLOOKUP($B21, Schroders!$D:$E, 2, FALSE) -> 4 | L21: =VLOOKUP($B21, LSEG!$D:$E, 2, FALSE) -> 4 | M21: =VLOOKUP($B21, Experian!$D:$E, 2, FALSE) -> 4 | N21: =VLOOKUP($B21, Wise!$D:$E, 2, FALSE) -> 4 | O21: =ROUND(AVERAGE($C21:$N21), 2) -> 3.75 | P21: =COUNTIF($C21:$N21, ">=3") & "/12" -> 12/12 | Q21: =COUNTIF($C21:$N21, ">=4") & "/12" -> 9/12
A22: CYG-04 | B22: Documented cyber risk assessment and stated risk appetite. | C22: =VLOOKUP($B22, HSBC!$D:$E, 2, FALSE) -> 4 | D22: =VLOOKUP($B22, Barclays!$D:$E, 2, FALSE) -> 4 | E22: =VLOOKUP($B22, Lloyds!$D:$E, 2, FALSE) -> 3 | F22: =VLOOKUP($B22, Aviva!$D:$E, 2, FALSE) -> 3 | G22: =VLOOKUP($B22, LG!$D:$E, 2, FALSE) -> 4 | H22: =VLOOKUP($B22, Prudential!$D:$E, 2, FALSE) -> 3 | I22: =VLOOKUP($B22, '3i'!$D:$E, 2, FALSE) -> 3 | J22: =VLOOKUP($B22, MG!$D:$E, 2, FALSE) -> 3 | K22: =VLOOKUP($B22, Schroders!$D:$E, 2, FALSE) -> 4 | L22: =VLOOKUP($B22, LSEG!$D:$E, 2, FALSE) -> 3 | M22: =VLOOKUP($B22, Experian!$D:$E, 2, FALSE) -> 4 | N22: =VLOOKUP($B22, Wise!$D:$E, 2, FALSE) -> 4 | O22: =ROUND(AVERAGE($C22:$N22), 2) -> 3.5 | P22: =COUNTIF($C22:$N22, ">=3") & "/12" -> 12/12 | Q22: =COUNTIF($C22:$N22, ">=4") & "/12" -> 6/12
A23: CYG-05 | B23: Asset inventory / asset management. | C23: =VLOOKUP($B23, HSBC!$D:$E, 2, FALSE) -> 2 | D23: =VLOOKUP($B23, Barclays!$D:$E, 2, FALSE) -> 2 | E23: =VLOOKUP($B23, Lloyds!$D:$E, 2, FALSE) -> 2 | F23: =VLOOKUP($B23, Aviva!$D:$E, 2, FALSE) -> 1 | G23: =VLOOKUP($B23, LG!$D:$E, 2, FALSE) -> 1 | H23: =VLOOKUP($B23, Prudential!$D:$E, 2, FALSE) -> 1 | I23: =VLOOKUP($B23, '3i'!$D:$E, 2, FALSE) -> 1 | J23: =VLOOKUP($B23, MG!$D:$E, 2, FALSE) -> 1 | K23: =VLOOKUP($B23, Schroders!$D:$E, 2, FALSE) -> 2 | L23: =VLOOKUP($B23, LSEG!$D:$E, 2, FALSE) -> 2 | M23: =VLOOKUP($B23, Experian!$D:$E, 2, FALSE) -> 2 | N23: =VLOOKUP($B23, Wise!$D:$E, 2, FALSE) -> 2 | O23: =ROUND(AVERAGE($C23:$N23), 2) -> 1.58 | P23: =COUNTIF($C23:$N23, ">=3") & "/12" -> 0/12 | Q23: =COUNTIF($C23:$N23, ">=4") & "/12" -> 0/12
A24: CYG-06 | B24: Supply-chain / third-party cyber risk governance. | C24: =VLOOKUP($B24, HSBC!$D:$E, 2, FALSE) -> 4 | D24: =VLOOKUP($B24, Barclays!$D:$E, 2, FALSE) -> 4 | E24: =VLOOKUP($B24, Lloyds!$D:$E, 2, FALSE) -> 3 | F24: =VLOOKUP($B24, Aviva!$D:$E, 2, FALSE) -> 3 | G24: =VLOOKUP($B24, LG!$D:$E, 2, FALSE) -> 3 | H24: =VLOOKUP($B24, Prudential!$D:$E, 2, FALSE) -> 4 | I24: =VLOOKUP($B24, '3i'!$D:$E, 2, FALSE) -> 3 | J24: =VLOOKUP($B24, MG!$D:$E, 2, FALSE) -> 3 | K24: =VLOOKUP($B24, Schroders!$D:$E, 2, FALSE) -> 4 | L24: =VLOOKUP($B24, LSEG!$D:$E, 2, FALSE) -> 3 | M24: =VLOOKUP($B24, Experian!$D:$E, 2, FALSE) -> 3 | N24: =VLOOKUP($B24, Wise!$D:$E, 2, FALSE) -> 3 | O24: =ROUND(AVERAGE($C24:$N24), 2) -> 3.33 | P24: =COUNTIF($C24:$N24, ">=3") & "/12" -> 12/12 | Q24: =COUNTIF($C24:$N24, ">=4") & "/12" -> 4/12
A25: CYG-07 | B25: Access control and identity management. | C25: =VLOOKUP($B25, HSBC!$D:$E, 2, FALSE) -> 3 | D25: =VLOOKUP($B25, Barclays!$D:$E, 2, FALSE) -> 3 | E25: =VLOOKUP($B25, Lloyds!$D:$E, 2, FALSE) -> 3 | F25: =VLOOKUP($B25, Aviva!$D:$E, 2, FALSE) -> 1 | G25: =VLOOKUP($B25, LG!$D:$E, 2, FALSE) -> 1 | H25: =VLOOKUP($B25, Prudential!$D:$E, 2, FALSE) -> 2 | I25: =VLOOKUP($B25, '3i'!$D:$E, 2, FALSE) -> 2 | J25: =VLOOKUP($B25, MG!$D:$E, 2, FALSE) -> 1 | K25: =VLOOKUP($B25, Schroders!$D:$E, 2, FALSE) -> 2 | L25: =VLOOKUP($B25, LSEG!$D:$E, 2, FALSE) -> 2 | M25: =VLOOKUP($B25, Experian!$D:$E, 2, FALSE) -> 3 | N25: =VLOOKUP($B25, Wise!$D:$E, 2, FALSE) -> 2 | O25: =ROUND(AVERAGE($C25:$N25), 2) -> 2.08 | P25: =COUNTIF($C25:$N25, ">=3") & "/12" -> 4/12 | Q25: =COUNTIF($C25:$N25, ">=4") & "/12" -> 0/12
A26: CYG-08 | B26: Data security (confidentiality, integrity, availability). | C26: =VLOOKUP($B26, HSBC!$D:$E, 2, FALSE) -> 4 | D26: =VLOOKUP($B26, Barclays!$D:$E, 2, FALSE) -> 4 | E26: =VLOOKUP($B26, Lloyds!$D:$E, 2, FALSE) -> 3 | F26: =VLOOKUP($B26, Aviva!$D:$E, 2, FALSE) -> 2 | G26: =VLOOKUP($B26, LG!$D:$E, 2, FALSE) -> 3 | H26: =VLOOKUP($B26, Prudential!$D:$E, 2, FALSE) -> 4 | I26: =VLOOKUP($B26, '3i'!$D:$E, 2, FALSE) -> 3 | J26: =VLOOKUP($B26, MG!$D:$E, 2, FALSE) -> 3 | K26: =VLOOKUP($B26, Schroders!$D:$E, 2, FALSE) -> 3 | L26: =VLOOKUP($B26, LSEG!$D:$E, 2, FALSE) -> 3 | M26: =VLOOKUP($B26, Experian!$D:$E, 2, FALSE) -> 4 | N26: =VLOOKUP($B26, Wise!$D:$E, 2, FALSE) -> 4 | O26: =ROUND(AVERAGE($C26:$N26), 2) -> 3.33 | P26: =COUNTIF($C26:$N26, ">=3") & "/12" -> 11/12 | Q26: =COUNTIF($C26:$N26, ">=4") & "/12" -> 5/12
A27: CYG-09 | B27: Operational resilience / ICT continuity. | C27: =VLOOKUP($B27, HSBC!$D:$E, 2, FALSE) -> 4 | D27: =VLOOKUP($B27, Barclays!$D:$E, 2, FALSE) -> 4 | E27: =VLOOKUP($B27, Lloyds!$D:$E, 2, FALSE) -> 4 | F27: =VLOOKUP($B27, Aviva!$D:$E, 2, FALSE) -> 3 | G27: =VLOOKUP($B27, LG!$D:$E, 2, FALSE) -> 4 | H27: =VLOOKUP($B27, Prudential!$D:$E, 2, FALSE) -> 4 | I27: =VLOOKUP($B27, '3i'!$D:$E, 2, FALSE) -> 3 | J27: =VLOOKUP($B27, MG!$D:$E, 2, FALSE) -> 3 | K27: =VLOOKUP($B27, Schroders!$D:$E, 2, FALSE) -> 4 | L27: =VLOOKUP($B27, LSEG!$D:$E, 2, FALSE) -> 4 | M27: =VLOOKUP($B27, Experian!$D:$E, 2, FALSE) -> 4 | N27: =VLOOKUP($B27, Wise!$D:$E, 2, FALSE) -> 3 | O27: =ROUND(AVERAGE($C27:$N27), 2) -> 3.67 | P27: =COUNTIF($C27:$N27, ">=3") & "/12" -> 12/12 | Q27: =COUNTIF($C27:$N27, ">=4") & "/12" -> 8/12
A28: CYG-10 | B28: Continuous monitoring / threat detection. | C28: =VLOOKUP($B28, HSBC!$D:$E, 2, FALSE) -> 4 | D28: =VLOOKUP($B28, Barclays!$D:$E, 2, FALSE) -> 4 | E28: =VLOOKUP($B28, Lloyds!$D:$E, 2, FALSE) -> 2 | F28: =VLOOKUP($B28, Aviva!$D:$E, 2, FALSE) -> 2 | G28: =VLOOKUP($B28, LG!$D:$E, 2, FALSE) -> 2 | H28: =VLOOKUP($B28, Prudential!$D:$E, 2, FALSE) -> 4 | I28: =VLOOKUP($B28, '3i'!$D:$E, 2, FALSE) -> 3 | J28: =VLOOKUP($B28, MG!$D:$E, 2, FALSE) -> 2 | K28: =VLOOKUP($B28, Schroders!$D:$E, 2, FALSE) -> 3 | L28: =VLOOKUP($B28, LSEG!$D:$E, 2, FALSE) -> 3 | M28: =VLOOKUP($B28, Experian!$D:$E, 2, FALSE) -> 4 | N28: =VLOOKUP($B28, Wise!$D:$E, 2, FALSE) -> 3 | O28: =ROUND(AVERAGE($C28:$N28), 2) -> 3 | P28: =COUNTIF($C28:$N28, ">=3") & "/12" -> 8/12 | Q28: =COUNTIF($C28:$N28, ">=4") & "/12" -> 4/12
A29: CYG-11 | B29: Incident response and management. | C29: =VLOOKUP($B29, HSBC!$D:$E, 2, FALSE) -> 4 | D29: =VLOOKUP($B29, Barclays!$D:$E, 2, FALSE) -> 4 | E29: =VLOOKUP($B29, Lloyds!$D:$E, 2, FALSE) -> 3 | F29: =VLOOKUP($B29, Aviva!$D:$E, 2, FALSE) -> 2 | G29: =VLOOKUP($B29, LG!$D:$E, 2, FALSE) -> 3 | H29: =VLOOKUP($B29, Prudential!$D:$E, 2, FALSE) -> 4 | I29: =VLOOKUP($B29, '3i'!$D:$E, 2, FALSE) -> 3 | J29: =VLOOKUP($B29, MG!$D:$E, 2, FALSE) -> 3 | K29: =VLOOKUP($B29, Schroders!$D:$E, 2, FALSE) -> 3 | L29: =VLOOKUP($B29, LSEG!$D:$E, 2, FALSE) -> 3 | M29: =VLOOKUP($B29, Experian!$D:$E, 2, FALSE) -> 4 | N29: =VLOOKUP($B29, Wise!$D:$E, 2, FALSE) -> 3 | O29: =ROUND(AVERAGE($C29:$N29), 2) -> 3.25 | P29: =COUNTIF($C29:$N29, ">=3") & "/12" -> 11/12 | Q29: =COUNTIF($C29:$N29, ">=4") & "/12" -> 4/12
A30: CYG-12 | B30: Threat-led penetration / resilience testing. | C30: =VLOOKUP($B30, HSBC!$D:$E, 2, FALSE) -> 4 | D30: =VLOOKUP($B30, Barclays!$D:$E, 2, FALSE) -> 4 | E30: =VLOOKUP($B30, Lloyds!$D:$E, 2, FALSE) -> 2 | F30: =VLOOKUP($B30, Aviva!$D:$E, 2, FALSE) -> 1 | G30: =VLOOKUP($B30, LG!$D:$E, 2, FALSE) -> 1 | H30: =VLOOKUP($B30, Prudential!$D:$E, 2, FALSE) -> 1 | I30: =VLOOKUP($B30, '3i'!$D:$E, 2, FALSE) -> 3 | J30: =VLOOKUP($B30, MG!$D:$E, 2, FALSE) -> 1 | K30: =VLOOKUP($B30, Schroders!$D:$E, 2, FALSE) -> 2 | L30: =VLOOKUP($B30, LSEG!$D:$E, 2, FALSE) -> 2 | M30: =VLOOKUP($B30, Experian!$D:$E, 2, FALSE) -> 3 | N30: =VLOOKUP($B30, Wise!$D:$E, 2, FALSE) -> 3 | O30: =ROUND(AVERAGE($C30:$N30), 2) -> 2.25 | P30: =COUNTIF($C30:$N30, ">=3") & "/12" -> 5/12 | Q30: =COUNTIF($C30:$N30, ">=4") & "/12" -> 2/12
... A33: CYG-15 | B33: Independent assurance / audit / management review. | C33: =VLOOKUP($B33, HSBC!$D:$E, 2, FALSE) -> 4 | D33: =VLOOKUP($B33, Barclays!$D:$E, 2, FALSE) -> 4 | E33: =VLOOKUP($B33, Lloyds!$D:$E, 2, FALSE) -> 3 | F33: =VLOOKUP($B33, Aviva!$D:$E, 2, FALSE) -> 3 | G33: =VLOOKUP($B33, LG!$D:$E, 2, FALSE) -> 4 | H33: =VLOOKUP($B33, Prudential!$D:$E, 2, FALSE) -> 4 | I33: =VLOOKUP($B33, '3i'!$D:$E, 2, FALSE) -> 2 | J33: =VLOOKUP($B33, MG!$D:$E, 2, FALSE) -> 3 | K33: =VLOOKUP($B33, Schroders!$D:$E, 2, FALSE) -> 4 | L33: =VLOOKUP($B33, LSEG!$D:$E, 2, FALSE) -> 3 | M33: =VLOOKUP($B33, Experian!$D:$E, 2, FALSE) -> 4 | N33: =VLOOKUP($B33, Wise!$D:$E, 2, FALSE) -> 4 | O33: =ROUND(AVERAGE($C33:$N33), 2) -> 3.5 | P33: =COUNTIF($C33:$N33, ">=3") & "/12" -> 11/12 | Q33: =COUNTIF($C33:$N33, ">=4") & "/12" -> 7/12
B34: Integration Indicators
A35: INT-01 | B35: A single committee / board body owns BOTH AI and cyber. | C35: =VLOOKUP($B35, HSBC!$D:$E, 2, FALSE) -> 4 | D35: =VLOOKUP($B35, Barclays!$D:$E, 2, FALSE) -> 3 | E35: =VLOOKUP($B35, Lloyds!$D:$E, 2, FALSE) -> 2 | F35: =VLOOKUP($B35, Aviva!$D:$E, 2, FALSE) -> 1 | G35: =VLOOKUP($B35, LG!$D:$E, 2, FALSE) -> 2 | H35: =VLOOKUP($B35, Prudential!$D:$E, 2, FALSE) -> 2 | I35: =VLOOKUP($B35, '3i'!$D:$E, 2, FALSE) -> 2 | J35: =VLOOKUP($B35, MG!$D:$E, 2, FALSE) -> 2 | K35: =VLOOKUP($B35, Schroders!$D:$E, 2, FALSE) -> 3 | L35: =VLOOKUP($B35, LSEG!$D:$E, 2, FALSE) -> 2 | M35: =VLOOKUP($B35, Experian!$D:$E, 2, FALSE) -> 3 | N35: =VLOOKUP($B35, Wise!$D:$E, 2, FALSE) -> 2 | O35: =ROUND(AVERAGE($C35:$N35), 2) -> 2.33 | P35: =COUNTIF($C35:$N35, ">=3") & "/12" -> 4/12 | Q35: =COUNTIF($C35:$N35, ">=4") & "/12" -> 1/12
A36: INT-02 | B36: CISO remit explicitly includes AI / joint accountability. | C36: =VLOOKUP($B36, HSBC!$D:$E, 2, FALSE) -> 2 | D36: =VLOOKUP($B36, Barclays!$D:$E, 2, FALSE) -> 2 | E36: =VLOOKUP($B36, Lloyds!$D:$E, 2, FALSE) -> 2 | F36: =VLOOKUP($B36, Aviva!$D:$E, 2, FALSE) -> 1 | G36: =VLOOKUP($B36, LG!$D:$E, 2, FALSE) -> 2 | H36: =VLOOKUP($B36, Prudential!$D:$E, 2, FALSE) -> 2 | I36: =VLOOKUP($B36, '3i'!$D:$E, 2, FALSE) -> 2 | J36: =VLOOKUP($B36, MG!$D:$E, 2, FALSE) -> 2 | K36: =VLOOKUP($B36, Schroders!$D:$E, 2, FALSE) -> 2 | L36: =VLOOKUP($B36, LSEG!$D:$E, 2, FALSE) -> 2 | M36: =VLOOKUP($B36, Experian!$D:$E, 2, FALSE) -> 2 | N36: =VLOOKUP($B36, Wise!$D:$E, 2, FALSE) -> 2 | O36: =ROUND(AVERAGE($C36:$N36), 2) -> 1.92 | P36: =COUNTIF($C36:$N36, ">=3") & "/12" -> 0/12 | Q36: =COUNTIF($C36:$N36, ">=4") & "/12" -> 0/12
A37: INT-03 | B37: Board reporting presents AI and cyber risk together. | C37: =VLOOKUP($B37, HSBC!$D:$E, 2, FALSE) -> 4 | D37: =VLOOKUP($B37, Barclays!$D:$E, 2, FALSE) -> 4 | E37: =VLOOKUP($B37, Lloyds!$D:$E, 2, FALSE) -> 3 | F37: =VLOOKUP($B37, Aviva!$D:$E, 2, FALSE) -> 1 | G37: =VLOOKUP($B37, LG!$D:$E, 2, FALSE) -> 2 | H37: =VLOOKUP($B37, Prudential!$D:$E, 2, FALSE) -> 3 | I37: =VLOOKUP($B37, '3i'!$D:$E, 2, FALSE) -> 2 | J37: =VLOOKUP($B37, MG!$D:$E, 2, FALSE) -> 2 | K37: =VLOOKUP($B37, Schroders!$D:$E, 2, FALSE) -> 3 | L37: =VLOOKUP($B37, LSEG!$D:$E, 2, FALSE) -> 3 | M37: =VLOOKUP($B37, Experian!$D:$E, 2, FALSE) -> 3 | N37: =VLOOKUP($B37, Wise!$D:$E, 2, FALSE) -> 3 | O37: =ROUND(AVERAGE($C37:$N37), 2) -> 2.75 | P37: =COUNTIF($C37:$N37, ">=3") & "/12" -> 8/12 | Q37: =COUNTIF($C37:$N37, ">=4") & "/12" -> 2/12
A38: INT-04 | B38: AI risk recorded in the enterprise / cyber risk register. | C38: =VLOOKUP($B38, HSBC!$D:$E, 2, FALSE) -> 3 | D38: =VLOOKUP($B38, Barclays!$D:$E, 2, FALSE) -> 3 | E38: =VLOOKUP($B38, Lloyds!$D:$E, 2, FALSE) -> 3 | F38: =VLOOKUP($B38, Aviva!$D:$E, 2, FALSE) -> 1 | G38: =VLOOKUP($B38, LG!$D:$E, 2, FALSE) -> 3 | H38: =VLOOKUP($B38, Prudential!$D:$E, 2, FALSE) -> 3 | I38: =VLOOKUP($B38, '3i'!$D:$E, 2, FALSE) -> 2 | J38: =VLOOKUP($B38, MG!$D:$E, 2, FALSE) -> 2 | K38: =VLOOKUP($B38, Schroders!$D:$E, 2, FALSE) -> 3 | L38: =VLOOKUP($B38, LSEG!$D:$E, 2, FALSE) -> 3 | M38: =VLOOKUP($B38, Experian!$D:$E, 2, FALSE) -> 3 | N38: =VLOOKUP($B38, Wise!$D:$E, 2, FALSE) -> 3 | O38: =ROUND(AVERAGE($C38:$N38), 2) -> 2.67 | P38: =COUNTIF($C38:$N38, ">=3") & "/12" -> 9/12 | Q38: =COUNTIF($C38:$N38, ">=4") & "/12" -> 0/12
A39: INT-05 | B39: Shared risk taxonomy across AI and cyber. | C39: =VLOOKUP($B39, HSBC!$D:$E, 2, FALSE) -> 2 | D39: =VLOOKUP($B39, Barclays!$D:$E, 2, FALSE) -> 2 | E39: =VLOOKUP($B39, Lloyds!$D:$E, 2, FALSE) -> 3 | F39: =VLOOKUP($B39, Aviva!$D:$E, 2, FALSE) -> 1 | G39: =VLOOKUP($B39, LG!$D:$E, 2, FALSE) -> 2 | H39: =VLOOKUP($B39, Prudential!$D:$E, 2, FALSE) -> 2 | I39: =VLOOKUP($B39, '3i'!$D:$E, 2, FALSE) -> 1 | J39: =VLOOKUP($B39, MG!$D:$E, 2, FALSE) -> 2 | K39: =VLOOKUP($B39, Schroders!$D:$E, 2, FALSE) -> 2 | L39: =VLOOKUP($B39, LSEG!$D:$E, 2, FALSE) -> 3 | M39: =VLOOKUP($B39, Experian!$D:$E, 2, FALSE) -> 3 | N39: =VLOOKUP($B39, Wise!$D:$E, 2, FALSE) -> 3 | O39: =ROUND(AVERAGE($C39:$N39), 2) -> 2.17 | P39: =COUNTIF($C39:$N39, ">=3") & "/12" -> 4/12 | Q39: =COUNTIF($C39:$N39, ">=4") & "/12" -> 0/12
A40: INT-06 | B40: AI sits within BOTH the model-risk and cyber-risk frameworks. | C40: =VLOOKUP($B40, HSBC!$D:$E, 2, FALSE) -> 3 | D40: =VLOOKUP($B40, Barclays!$D:$E, 2, FALSE) -> 3 | E40: =VLOOKUP($B40, Lloyds!$D:$E, 2, FALSE) -> 3 | F40: =VLOOKUP($B40, Aviva!$D:$E, 2, FALSE) -> 1 | G40: =VLOOKUP($B40, LG!$D:$E, 2, FALSE) -> 2 | H40: =VLOOKUP($B40, Prudential!$D:$E, 2, FALSE) -> 2 | I40: =VLOOKUP($B40, '3i'!$D:$E, 2, FALSE) -> 1 | J40: =VLOOKUP($B40, MG!$D:$E, 2, FALSE) -> 2 | K40: =VLOOKUP($B40, Schroders!$D:$E, 2, FALSE) -> 2 | L40: =VLOOKUP($B40, LSEG!$D:$E, 2, FALSE) -> 2 | M40: =VLOOKUP($B40, Experian!$D:$E, 2, FALSE) -> 3 | N40: =VLOOKUP($B40, Wise!$D:$E, 2, FALSE) -> 3 | O40: =ROUND(AVERAGE($C40:$N40), 2) -> 2.25 | P40: =COUNTIF($C40:$N40, ">=3") & "/12" -> 5/12 | Q40: =COUNTIF($C40:$N40, ">=4") & "/12" -> 0/12
A41: INT-07 | B41: Cyber controls embedded in the AI lifecycle. | C41: =VLOOKUP($B41, HSBC!$D:$E, 2, FALSE) -> 2 | D41: =VLOOKUP($B41, Barclays!$D:$E, 2, FALSE) -> 2 | E41: =VLOOKUP($B41, Lloyds!$D:$E, 2, FALSE) -> 2 | F41: =VLOOKUP($B41, Aviva!$D:$E, 2, FALSE) -> 1 | G41: =VLOOKUP($B41, LG!$D:$E, 2, FALSE) -> 3 | H41: =VLOOKUP($B41, Prudential!$D:$E, 2, FALSE) -> 2 | I41: =VLOOKUP($B41, '3i'!$D:$E, 2, FALSE) -> 1 | J41: =VLOOKUP($B41, MG!$D:$E, 2, FALSE) -> 2 | K41: =VLOOKUP($B41, Schroders!$D:$E, 2, FALSE) -> 2 | L41: =VLOOKUP($B41, LSEG!$D:$E, 2, FALSE) -> 1 | M41: =VLOOKUP($B41, Experian!$D:$E, 2, FALSE) -> 3 | N41: =VLOOKUP($B41, Wise!$D:$E, 2, FALSE) -> 1 | O41: =ROUND(AVERAGE($C41:$N41), 2) -> 1.83 | P41: =COUNTIF($C41:$N41, ">=3") & "/12" -> 2/12 | Q41: =COUNTIF($C41:$N41, ">=4") & "/12" -> 0/12
A42: INT-08 | B42: AI-specific threats addressed (adversarial, poisoning, model exfiltration). | C42: =VLOOKUP($B42, HSBC!$D:$E, 2, FALSE) -> 2 | D42: =VLOOKUP($B42, Barclays!$D:$E, 2, FALSE) -> 3 | E42: =VLOOKUP($B42, Lloyds!$D:$E, 2, FALSE) -> 2 | F42: =VLOOKUP($B42, Aviva!$D:$E, 2, FALSE) -> 1 | G42: =VLOOKUP($B42, LG!$D:$E, 2, FALSE) -> 2 | H42: =VLOOKUP($B42, Prudential!$D:$E, 2, FALSE) -> 3 | I42: =VLOOKUP($B42, '3i'!$D:$E, 2, FALSE) -> 1 | J42: =VLOOKUP($B42, MG!$D:$E, 2, FALSE) -> 3 | K42: =VLOOKUP($B42, Schroders!$D:$E, 2, FALSE) -> 2 | L42: =VLOOKUP($B42, LSEG!$D:$E, 2, FALSE) -> 2 | M42: =VLOOKUP($B42, Experian!$D:$E, 2, FALSE) -> 2 | N42: =VLOOKUP($B42, Wise!$D:$E, 2, FALSE) -> 2 | O42: =ROUND(AVERAGE($C42:$N42), 2) -> 2.08 | P42: =COUNTIF($C42:$N42, ">=3") & "/12" -> 3/12 | Q42: =COUNTIF($C42:$N42, ">=4") & "/12" -> 0/12
A43: INT-09 | B43: Shared data governance across AI and security. | C43: =VLOOKUP($B43, HSBC!$D:$E, 2, FALSE) -> 3 | D43: =VLOOKUP($B43, Barclays!$D:$E, 2, FALSE) -> 3 | E43: =VLOOKUP($B43, Lloyds!$D:$E, 2, FALSE) -> 3 | F43: =VLOOKUP($B43, Aviva!$D:$E, 2, FALSE) -> 2 | G43: =VLOOKUP($B43, LG!$D:$E, 2, FALSE) -> 2 | H43: =VLOOKUP($B43, Prudential!$D:$E, 2, FALSE) -> 3 | I43: =VLOOKUP($B43, '3i'!$D:$E, 2, FALSE) -> 1 | J43: =VLOOKUP($B43, MG!$D:$E, 2, FALSE) -> 2 | K43: =VLOOKUP($B43, Schroders!$D:$E, 2, FALSE) -> 2 | L43: =VLOOKUP($B43, LSEG!$D:$E, 2, FALSE) -> 2 | M43: =VLOOKUP($B43, Experian!$D:$E, 2, FALSE) -> 4 | N43: =VLOOKUP($B43, Wise!$D:$E, 2, FALSE) -> 2 | O43: =ROUND(AVERAGE($C43:$N43), 2) -> 2.42 | P43: =COUNTIF($C43:$N43, ">=3") & "/12" -> 5/12 | Q43: =COUNTIF($C43:$N43, ">=4") & "/12" -> 1/12
A44: INT-10 | B44: AI incidents run through the cyber incident-response process. | C44: =VLOOKUP($B44, HSBC!$D:$E, 2, FALSE) -> 1 | D44: =VLOOKUP($B44, Barclays!$D:$E, 2, FALSE) -> 2 | E44: =VLOOKUP($B44, Lloyds!$D:$E, 2, FALSE) -> 1 | F44: =VLOOKUP($B44, Aviva!$D:$E, 2, FALSE) -> 1 | G44: =VLOOKUP($B44, LG!$D:$E, 2, FALSE) -> 1 | H44: =VLOOKUP($B44, Prudential!$D:$E, 2, FALSE) -> 2 | I44: =VLOOKUP($B44, '3i'!$D:$E, 2, FALSE) -> 1 | J44: =VLOOKUP($B44, MG!$D:$E, 2, FALSE) -> 1 | K44: =VLOOKUP($B44, Schroders!$D:$E, 2, FALSE) -> 1 | L44: =VLOOKUP($B44, LSEG!$D:$E, 2, FALSE) -> 1 | M44: =VLOOKUP($B44, Experian!$D:$E, 2, FALSE) -> 2 | N44: =VLOOKUP($B44, Wise!$D:$E, 2, FALSE) -> 1 | O44: =ROUND(AVERAGE($C44:$N44), 2) -> 1.25 | P44: =COUNTIF($C44:$N44, ">=3") & "/12" -> 0/12 | Q44: =COUNTIF($C44:$N44, ">=4") & "/12" -> 0/12
...

Sheet Scoring Rubrics
B2: Scoring Rubrics
B4: Maturity scale — AI Governance (AIG) and Cyber Governance (CYG)
B5: Level | C5: Label | D5: Definition
B6: 1 | C6: Initial | D6: Absent or ad hoc - the governance activity is not mentioned, or appears only in passing with no substance.
B7: 2 | C7: Developing | D7: Acknowledged in generic terms; referenced but with no specifics, owners, or evidence it operates. Informal.
B8: 3 | C8: Defined | D8: A specific policy, structure or process is described, documented and applied organisation-wide.
B9: 4 | C9: Managed | D9: Owned and resourced; named accountability, cadence, metrics, or evidence the activity actually operates.
B10: 5 | C10: Optimising | D10: Independently assured or benchmarked, reviewed, and continuously improved (e.g. external audit / certification).
B13: Linkage scale — Integration (INT)
B14: Level | C14: Label | D14: Definition
B15: 1 | C15: Siloed | D15: AI and cyber governance are handled separately, with no cross-reference between them.
B16: 2 | C16: Aware | D16: Both are present and occasionally cross-referenced, but no shared mechanism exists.
B17: 3 | C17: Coordinated | D17: An explicit linkage is described on this dimension (e.g. AI named within the cyber policy).
B18: 4 | C18: Integrated | D18: A shared mechanism is operating (e.g. one committee, one risk register covering both).
B19: 5 | C19: Unified | D19: The two domains are fully fused on this dimension: jointly governed, jointly assured, continuously improved.

Sheet Codebook_Worksheet
A1: Firm: | B1: HSBC Holdings plc | E1: Sub-sector: | F1: Banking
A3: Pillar | B3: ID | C3: Dimension | D3: Indicator | E3: Score 1–5 | F3: Evidence summary | G3: Page ref | H3: Notes
A4: AI | B4: AIG-01 | C4: Leadership & Accountability | D4: Board / top-management-approved responsible-AI policy or principles.
A5: AI | B5: AIG-02 | C5: Leadership & Accountability | D5: Board / committee oversight of AI with a named senior owner (e.g. CAIO or accountable executive).
A6: AI | B6: AIG-03 | C6: Leadership & Accountability | D6: Defined AI roles, responsibilities and competence / resourcing.
A7: AI | B7: AIG-04 | C7: Risk Management | D7: Documented AI risk assessment process and stated AI risk appetite / tolerance.
A8: AI | B8: AIG-05 | C8: Risk Management | D8: AI/ML brought within the firm's model risk management framework.
A9: AI | B9: AIG-06 | C9: Risk Management | D9: AI system / model inventory maintained.
A10: AI | B10: AIG-07 | C10: Lifecycle & Data | D10: Responsible-AI lifecycle controls (development → validation/V&V → operation).
A11: AI | B11: AIG-08 | C11: Lifecycle & Data | D11: Data governance for AI (data quality, provenance, lineage).
A12: AI | B12: AIG-09 | C12: Lifecycle & Data | D12: AI impact assessment on customers / individuals.
A13: AI | B13: AIG-10 | C13: Transparency & Trustworthiness | D13: Fairness and harmful-bias management.
A14: AI | B14: AIG-11 | C14: Transparency & Trustworthiness | D14: Transparency and explainability to users / affected parties.
A15: AI | B15: AIG-12 | C15: Transparency & Trustworthiness | D15: Third-party / vendor AI risk governance.
... A48: INT | B48: INT-15 | C48: Assurance & Improvement | D48: Board links AI strategy to cyber resilience.
A50: SUMMARY
A51: AI governance — mean maturity | B51: =IFERROR(AVERAGE(E4,E5,E6,E7,E8,E9,E10,E11,E12,E13,E14,E15,E16,E17,E18),"")
A52: Cyber governance — mean maturity | B52: =IFERROR(AVERAGE(E19,E20,E21,E22,E23,E24,E25,E26,E27,E28,E29,E30,E31,E32,E33),"")
A53: Integration — mean linkage | B53: =IFERROR(AVERAGE(E34,E35,E36,E37,E38,E39,E40,E41,E42,E43,E44,E45,E46,E47,E48),"")
A54: AI–cyber maturity gap (cyber − AI) | B54: =IFERROR(B52-B51,"")
A56: Shared-dimension comparison (comparable axes only — dims 1, 2, 5)
A57: Dimension | B57: AI mean | C57: Cyber mean | D57: Gap | E57: Integration mean
A58: 1 Leadership & Accountability | B58: =IFERROR(AVERAGE(E4,E5,E6),"") | C58: =IFERROR(AVERAGE(E19,E20,E21),"") | D58: =IFERROR(C58-B58,"") | E58: =IFERROR(AVERAGE(E34,E35,E36),"")
A59: 2 Risk Management | B59: =IFERROR(AVERAGE(E7,E8,E9),"") | C59: =IFERROR(AVERAGE(E22,E23,E24),"") | D59: =IFERROR(C59-B59,"") | E59: =IFERROR(AVERAGE(E37,E38,E39),"")
A60: 5 Assurance & Improvement | B60: =IFERROR(AVERAGE(E16,E17,E18),"") | C60: =IFERROR(AVERAGE(E31,E32,E33),"") | D60: =IFERROR(C60-B60,"") | E60: =IFERROR(AVERAGE(E46,E47,E48),"")
A61: Lifecycle & Data | E61: =IFERROR(ROUND(AVERAGE(E40:E42),2),"")
A62: Detect & Response | E62: =IFERROR(ROUND(AVERAGE(E43:E45),2),"")

Sheet HSBC
A1: Firm: | B1: HSBC Holdings plc | E1: Sub-sector: | F1: Banking
A3: Pillar | B3: ID | C3: Dimension | D3: Indicator | E3: Score 1–5 | F3: Evidence summary | G3: Page ref | H3: Notes
A4: AI | B4: AIG-01 | C4: Leadership & Accountability | D4: Board / top-management-approved responsible-AI policy or principles. | E4: 3 | F4: HSBC publishes Principles for the Ethical Use of Data and AI and maintains a group-wide AI oversight, governance, lifecycle-management and risk framework. | G4: printed p.30, 59
A5: AI | B5: AIG-02 | C5: Leadership & Accountability | D5: Board / committee oversight of AI with a named senior owner (e.g. CAIO or accountable executive). | E5: 3 | F5: A group-wide AI oversight and governance framework operates and the Group Technology & Operations Committee reviews and challenges GenAI strategy; no single named AI executive (e.g. CAIO) is disclosed. | G5: printed p.30, 209, 215 | H5: Confirm whether GTO is a board or executive committee.
A6: AI | B6: AIG-03 | C6: Leadership & Accountability | D6: Defined AI roles, responsibilities and competence / resourcing. | E6: 4 | F6: AI Academy provides AI literacy, responsible-AI and AI-ethics training with digital badging and an AI Ambassador mentorship programme; over 100 GenAI solutions reported in use. | G6: printed p.8, 11, 56
A7: AI | B7: AIG-04 | C7: Risk Management | D7: Documented AI risk assessment process and stated AI risk appetite / tolerance. | E7: 3 | F7: HSBC reports developing a governance framework to manage risks from AI techniques (machine learning, agentic AI); AI/ML models are managed within model risk appetite. Framework described as in development. | G7: printed p.104, 181
A8: AI | B8: AIG-05 | C8: Risk Management | D8: AI/ML brought within the firm's model risk management framework. | E8: 4 | F8: AI/ML models sit within the Model Risk Management framework, which HSBC enhanced to meet the PRA's SS1/23; an AI-specific governance overlay is still being developed. | G8: printed p.104, 181 | H8: Strongest AI-governance indicator; AI-specific framework still developing.
A9: AI | B9: AIG-06 | C9: Risk Management | D9: AI system / model inventory maintained. | E9: 3 | F9: Models are managed across the model landscape via MRM with a library of model risk controls and a model risk committee structure; no AI-specific inventory is named. | G9: printed p.104, 182
A10: AI | B10: AIG-07 | C10: Lifecycle & Data | D10: Responsible-AI lifecycle controls (development → validation/V&V → operation). | E10: 3 | F10: The MRM lifecycle (development, independent validation, monitoring) applies to models including AI/ML; GenAI governance and approval processes are being streamlined. AI-specific lifecycle controls developing. | G10: printed p.104, 215
A11: AI | B11: AIG-08 | C11: Lifecycle & Data | D11: Data governance for AI (data quality, provenance, lineage). | E11: 3 | F11: A Group-wide data risk policy (reviewed annually) governs data and privacy; a Group data strategy and operating model is under development; ML is used in data infrastructure. AI-specific data governance not separately detailed. | G11: printed p.64, 215
A12: AI | B12: AIG-09 | C12: Lifecycle & Data | D12: AI impact assessment on customers / individuals. | E12: 2 | F12: Potential social impacts of AI on communities are noted in the human-rights review; no formal AI impact assessment on customers is disclosed. | G12: printed p.59
A13: AI | B13: AIG-10 | C13: Transparency & Trustworthiness | D13: Fairness and harmful-bias management. | E13: 2 | F13: AI principles cover the ethical use of data and AI; no explicit AI fairness or bias testing, metrics or remediation is disclosed. | G13: printed p.59
A14: AI | B14: AIG-11 | C14: Transparency & Trustworthiness | D14: Transparency and explainability to users / affected parties. | E14: 2 | F14: Transparency to customers on personal-data processing is disclosed and AI principles reference privacy; AI explainability is not explicitly addressed. | G14: printed p.59, 64
A15: AI | B15: AIG-12 | C15: Transparency & Trustworthiness | D15: Third-party / vendor AI risk governance. | E15: 2 | F15: A third-party security risk management process covers cyber/ICT suppliers; AI-specific vendor governance is not separately disclosed. | G15: printed p.64
A16: AI | B16: AIG-13 | C16: Assurance & Improvement | D16: Monitoring and measurement of AI performance and controls. | E16: 3 | F16: Model monitoring, model risk appetite metrics and independent validation within MRM cover AI/ML models; model risk is reported to the Group Risk Committee. | G16: printed p.106, 182
A17: AI | B17: AIG-14 | C17: Assurance & Improvement | D17: AI testing, incident management and escalation. | E17: 2 | F17: GenAI governance/approval and MRM controls are referenced; an AI-specific testing and incident-escalation process is not explicitly disclosed. | G17: printed p.215
A18: AI | B18: AIG-15 | C18: Assurance & Improvement | D18: Independent assurance / audit / management review of AI governance. | E18: 3 | F18: MRM independent validation (second line) and Global Internal Audit (third line) assure model risk including AI/ML; AI-specific independent assurance is not separately framed. | G18: printed p.99, 182
A19: CYBER | B19: CYG-01 | C19: Leadership & Accountability | D19: Board-approved cybersecurity / information-security policy. | E19: 4 | F19: Cybersecurity policy and governance operate within a three-lines-of-defence model aligned to the enterprise risk management framework; a Group-wide data risk policy is reviewed annually. | G19: printed p.64
A20: CYBER | B20: CYG-02 | C20: Leadership & Accountability | D20: Board oversight of cyber risk with a named senior owner (CISO). | E20: 4 | F20: Cyber risk is led and coordinated by a Global Chief Information Security Officer (CISO); the Group Technology & Operations Committee receives CISO/GCIO updates on the cybersecurity programme. | G20: printed p.64, 215
... A22: CYBER | B22: CYG-04 | C22: Risk Management | D22: Documented cyber risk assessment and stated risk appetite. | E22: 4 | F22: Technology and cybersecurity risk is a named top/emerging risk managed within risk appetite; resilience risk is measured against agreed appetite. | G22: printed p.31, 101, 106
A23: CYBER | B23: CYG-05 | C23: Risk Management | D23: Asset inventory / asset management. | E23: 2 | F23: An extensive technology landscape is referenced, but an explicit asset inventory / asset management capability is not disclosed. | G23: printed p.64, 101 | H23: Not disclosed as such — low-yield in annual reports.
A24: CYBER | B24: CYG-06 | C24: Risk Management | D24: Supply-chain / third-party cyber risk governance. | E24: 4 | F24: A third-party security risk management process assesses suppliers against HSBC's cybersecurity standards; third-party cyber exposure is tracked and reported to the Group Technology & Operations Committee. | G24: printed p.64, 215
A25: CYBER | B25: CYG-07 | C25: Protection & Resilience | D25: Access control and identity management. | E25: 3 | F25: Defence-in-depth controls reduce unauthorised access and exploitation of vulnerabilities; explicit identity- and access-management detail is not disclosed. | G25: printed p.64
A26: CYBER | B26: CYG-08 | C26: Protection & Resilience | D26: Data security (confidentiality, integrity, availability). | E26: 4 | F26: Defence-in-depth security layers, data-leakage controls, and routinely tested data backup and disaster recovery protect confidentiality, integrity and availability. | G26: printed p.64
A27: CYBER | B27: CYG-09 | C27: Protection & Resilience | D27: Operational resilience / ICT continuity. | E27: 4 | F27: Operational resilience is operated per the Risk Management Framework around Important Business Services; a resilience-risk target operating model, incident-management plans and backup/DR testing are described. | G27: printed p.64, 180
A28: CYBER | B28: CYG-10 | C28: Detection & Response | D28: Continuous monitoring / threat detection. | E28: 4 | F28: Round-the-clock security operations support detect/respond; a dedicated cyber intelligence and threat-analysis team collects internal and external threat information. | G28: printed p.64
A29: CYBER | B29: CYG-11 | C29: Detection & Response | D29: Incident response and management. | E29: 4 | F29: Procedures cover cyber incident identification, investigation, mitigation and reporting; incident-management plans, post-incident reviews and playbook testing are described. | G29: printed p.64, 180, 215
A30: CYBER | B30: CYG-12 | C30: Detection & Response | D30: Threat-led penetration / resilience testing. | E30: 4 | F30: External independent third parties are engaged to support penetration testing and threat-led penetration testing. | G30: printed p.64
A31: CYBER | B31: CYG-13 | C31: Assurance & Improvement | D31: Security monitoring metrics and board reporting. | E31: 4 | F31: The Group Technology & Operations Committee receives updates and metrics on all key components of the cybersecurity programme, including incidents and third-party exposure. | G31: printed p.215
A32: CYBER | B32: CYG-14 | C32: Assurance & Improvement | D32: Security awareness and training. | E32: 4 | F32: Cyber training and awareness programmes operate, alongside mandatory data privacy and security training for employees. | G32: printed p.64
A33: CYBER | B33: CYG-15 | C33: Assurance & Improvement | D33: Independent assurance / audit / management review. | E33: 4 | F33: Global Internal Audit (third line) provides independent assurance over risk management including cyber; results are reported to the Group Audit Committee and Group Risk Committee. | G33: printed p.99, 206
A34: INT | B34: INT-01 | C34: Leadership & Accountability | D34: A single committee / board body owns BOTH AI and cyber. | E34: 4 | F34: The Group Technology & Operations Committee oversees GenAI strategy, cybersecurity and data within one committee — a shared governance body covering both domains. | G34: printed p.215 | H34: Keystone integration evidence (single committee covers AI + cyber).
A35: INT | B35: INT-02 | C35: Leadership & Accountability | D35: CISO remit explicitly includes AI / joint accountability. | E35: 2 | F35: The CISO leads cyber and the cyber function addresses AI as an emerging technology risk; AI governance itself sits within model risk rather than the CISO remit. | G35: printed p.64, 181
A36: INT | B36: INT-03 | C36: Leadership & Accountability | D36: Board reporting presents AI and cyber risk together. | E36: 4 | F36: GenAI strategy and cybersecurity are presented as adjacent areas of focus within the same Group Technology & Operations Committee report. | G36: printed p.215
A37: INT | B37: INT-04 | C37: Risk Management | D37: AI risk recorded in the enterprise / cyber risk register. | E37: 3 | F37: AI/model risk is a named top/emerging risk within the enterprise risk framework and is reported to the Group Risk Committee; not framed as a single AI-in-cyber-register entry. | G37: printed p.104, 182
A38: INT | B38: INT-05 | C38: Risk Management | D38: Shared risk taxonomy across AI and cyber. | E38: 2 | F38: The resilience-risk taxonomy covers technology/cyber and data; model risk is a separate taxonomy; no shared AI-cyber taxonomy is disclosed. | G38: printed p.180, 182
A39: INT | B39: INT-06 | C39: Risk Management | D39: AI sits within BOTH the model-risk and cyber-risk frameworks. | E39: 3 | F39: AI/ML is firmly within model risk (MRM/SS1/23) and the cybersecurity function separately addresses AI as an emerging technology risk — AI features in both frameworks. | G39: printed p.64, 104, 181
A40: INT | B40: INT-07 | C40: Lifecycle & Data | D40: Cyber controls embedded in the AI lifecycle. | E40: 2 | F40: Cybersecurity notes preparedness for emerging technology risks such as AI; cyber controls embedded within the AI development lifecycle are not explicitly disclosed. | G40: printed p.64
A41: INT | B41: INT-08 | C41: Lifecycle & Data | D41: AI-specific threats addressed (adversarial, poisoning, model exfiltration). | E41: 2 | F41: AI is named as an emerging technology risk within cybersecurity preparedness; AI-specific threats (adversarial, data poisoning, model exfiltration) are not specifically disclosed. | G41: printed p.64
A42: INT | B42: INT-09 | C42: Lifecycle & Data | D42: Shared data governance across AI and security. | E42: 3 | F42: A Group-wide data risk policy spans data, privacy and security across businesses; AI uses the same data governance, but AI-security data integration is not separately framed. | G42: printed p.64
...

Sheet Barclays
A1: Firm: | E1: Sub-sector: | H1: Date
B2: Barclays PLC | F2: Banking
A3: Pillar | B3: ID | C3: Dimension | D3: Indicator | E3: Score 1–5 | F3: Evidence summary | G3: Page ref | H3: Notes
A4: AI | B4: AIG-01 | C4: Leadership & Accountability | D4: Board / top-management-approved responsible-AI policy or principles. | E4: 4 | F4: Barclays operates an AI Policy and a new AI Standard with Ethical AI Principles for enterprise-wide, ethical and lawful AI use; the Board reviews the approach to AI governance and the related policies/standards. | G4: printed p.252, 341, 125
A5: AI | B5: AIG-02 | C5: Leadership & Accountability | D5: Board / committee oversight of AI with a named senior owner (e.g. CAIO or accountable executive). | E5: 4 | F5: The Board has close oversight of AI governance, policies and use cases and deepened its AI expertise through external engagement; the Board Risk Committee considers AI-related threats. No named Chief AI Officer disclosed. | G5: printed p.125, 142
A6: AI | B6: AIG-03 | C6: Leadership & Accountability | D6: Defined AI roles, responsibilities and competence / resourcing. | E6: 3 | F6: Board and ExCo deepened AI/technology understanding (incl. external/academic engagement); additional model roles and responsibilities established; AI/ML initiatives launched. AI-specific staff training less detailed. | G6: printed p.125, 182, 341
